<?xml version="1.0"?>
<robot
  name="armadillo_base" description="ARMadillo robot base">
  
    <link name="base_footprint"/>
  
 <joint name="base_footprint_joint" type="fixed">
    <parent link="base_footprint"/>
    <child link="base_link"/>
    <origin xyz="0.00 0.00 0.095" rpy="0.0 0.0 0.0"/>
  </joint> 
  
  <link
    name="base_link">
    <inertial>
      <origin
        xyz="-0.058417 0.00010778 0.15422"
        rpy="0 0 0" />
      <mass
        value="30.6548" />
      <inertia
        ixx="0.61639"
        ixy="-9.1727E-05"
        ixz="-0.093044"
        iyy="0.57997"
        iyz="5.3231E-05"
        izz="0.36693" />
    </inertial>
   <visual name='chassis'>
      <origin
        xyz="0 0 0"
        rpy="0 0 0" />
      <geometry>
        <mesh
          filename="package://robotican_armadillo/description/meshes/base_link.STL" />
      </geometry>
      <material
        name="">
        <color
          rgba="0.79216 0.81961 0.93333 1" />
      </material>
    </visual>

     <collision name='base_collision'>
       <origin
        xyz="0 0 0"
        rpy="0 0 0" />
      <geometry>
        <mesh
          filename="package://robotican_armadillo/description/meshes/base_link.STL" />
      </geometry>
          </collision>

      <collision name='caster_collision'>
      <origin
        xyz="-0.30 0 -0.0475"
        rpy="0 0 0" />
            <geometry>
              <sphere radius="0.0475"/>
            </geometry>
            <surface>
              <friction>
                <ode>
                  <mu>0</mu>
                  <mu2>0</mu2>
                  <slip1>1.0</slip1>
                  <slip2>1.0</slip2>
                </ode>
              </friction>
            </surface>
          </collision>
	<!--  <visual name='caster_visual'>
	 <origin
        xyz="-0.30 0 -0.0475"
        rpy="0 0 0" />
            <geometry>
	    <sphere radius="0.0475"/>
            </geometry>
	  </visual> -->
  </link>

  


  <link
    name="front_cam_link">
    <inertial>
      <origin
        xyz="-0.0060072 3.3793E-07 0.0005545"
        rpy="0 0 0" />
      <mass
        value="0.01942" />
      <inertia
        ixx="3.9185E-06"
        ixy="-2.0999E-11"
        ixz="-4.949E-08"
        iyy="2.1089E-06"
        iyz="-3.146E-10"
        izz="2.8316E-06" />
    </inertial>
    <visual>
      <origin
        xyz="0 0 0"
        rpy="0 0 0" />
      <geometry>
        <mesh
          filename="package://robotican_armadillo/description/meshes/front_cam_link.STL" />
      </geometry>
      <material
        name="">
        <color
          rgba="0.29804 0.29804 0.29804 1" />
      </material>
    </visual>
    <collision>
      <origin
        xyz="0 0 0"
        rpy="0 0 0" />
      <geometry>
        <mesh
          filename="package://robotican_armadillo/description/meshes/front_cam_link.STL" />
      </geometry>
    </collision>
  </link>
  <joint
    name="front_cam_joint"
    type="fixed">
    <origin
      xyz="0.21658 0 0.0187"
      rpy="0 0 0" />
    <parent
      link="base_link" />
    <child
      link="front_cam_link" />
    <axis
      xyz="0 0 0" />
  </joint>
  <link
    name="left_urf_link">
    <inertial>
      <origin
        xyz="-0.0094226 -0.00019318 -1.6889E-05"
        rpy="0 0 0" />
      <mass
        value="0.0027749" />
      <inertia
        ixx="1.2831E-07"
        ixy="3.1103E-09"
        ixz="1.5459E-10"
        iyy="1.2843E-07"
        iyz="-4.3527E-09"
        izz="1.1894E-07" />
    </inertial>
    <visual>
      <origin
        xyz="0 0 0"
        rpy="0 ${M_PI/2} 0" />
      <geometry>
	<!--  <mesh filename="package://robotican_armadillo/description/meshes/left_urf_link.STL" /> -->
	<cylinder  length="0.005" radius="0.008"/> 
      </geometry>
      <material
        name="">
        <color
          rgba="0 0 0 1" />
      </material>
    </visual>
    <collision>
      <origin
        xyz="0 0 0"
        rpy="0 ${M_PI/2} 0" />
      <geometry>
       	<!--  <mesh filename="package://robotican_armadillo/description/meshes/left_urf_link.STL" /> -->
	<cylinder  length="0.01" radius="0.008"/> 
      </geometry>
    </collision>
  </link>
  <joint
    name="left_urf_joint"
    type="fixed">
    <origin
      xyz="-0.038417 0.25288 0.1498"
      rpy="0 0 1.5708" />
    <parent
      link="base_link" />
    <child
      link="left_urf_link" />
    <axis
      xyz="0 0 0" />
  </joint>
  <link
    name="right_urf_link">
    <inertial>
      <origin
        xyz="-0.0094226 1.6889E-05 -0.00019318"
        rpy="0 0 0" />
      <mass
        value="0.0027749" />
      <inertia
        ixx="1.2831E-07"
        ixy="-1.5459E-10"
        ixz="3.1103E-09"
        iyy="1.1894E-07"
        iyz="4.3527E-09"
        izz="1.2843E-07" />
    </inertial>
    <visual>
      <origin
        xyz="0 0 0"
        rpy="0 ${M_PI/2} 0" />
      <geometry>
	<cylinder  length="0.005" radius="0.008"/> 
      </geometry>
      <material
        name="">
        <color
          rgba="0 0 0 1" />
      </material>
    </visual>
    <collision>
      <origin
        xyz="0 0 0"
         rpy="0 ${M_PI/2} 0" />
      <geometry>
	<cylinder  length="0.005" radius="0.008"/> 
      </geometry>
    </collision>
  </link>
  <joint
    name="right_urf_joint"
    type="fixed">
    <origin
      xyz="-0.038417 -0.25288 0.1498"
      rpy="0 0 -1.5708" />
    <parent
      link="base_link" />
    <child
      link="right_urf_link" />
    <axis
      xyz="0 0 0" />
  </joint>
  <link
    name="rear_urf_link">
    <inertial>
      <origin
        xyz="-0.0094226 -1.6889E-05 0.00019318"
        rpy="0 0 0" />
      <mass
        value="0.0027749" />
      <inertia
        ixx="1.2831E-07"
        ixy="1.5459E-10"
        ixz="-3.1103E-09"
        iyy="1.1894E-07"
        iyz="4.3527E-09"
        izz="1.2843E-07" />
    </inertial>
    <visual>
      <origin
        xyz="0 0 0"
        rpy="0 ${M_PI/2} 0" />
      <geometry>
<!--         <mesh  filename="package://robotican_armadillo/description/meshes/rear_urf_link.STL" /> -->
	<cylinder  length="0.005" radius="0.008"/> 
      </geometry>
      <material
        name="">
        <color
          rgba="0 0 0 1" />
      </material>
    </visual>
    <collision>
      <origin
        xyz="0 0 0"
        rpy="0 ${M_PI/2} 0" />
      <geometry>
<!--         <mesh filename="package://robotican_armadillo/description/meshes/rear_urf_link.STL" /> -->
	<cylinder  length="0.01" radius="0.008"/> 
      </geometry>
    </collision>
  </link>
  <joint
    name="rear_urf_joint"
    type="fixed">
    <origin
      xyz="-0.28028 0 0.1498"
      rpy="0 0 3.1416" />
    <parent
      link="base_link" />
    <child
      link="rear_urf_link" />
    <axis
      xyz="0 0 0" />
  </joint>
  <link
    name="left_wheel_link">
    <inertial>
      <origin
        xyz="5.6549E-06 -0.050799 0.030167"
        rpy="0 0 0" />
      <mass
        value="1.8524" />
      <inertia
        ixx="0.0069046"
        ixy="-3.8717E-08"
        ixz="2.0707E-07"
        iyy="0.013153"
        iyz="-1.0124E-07"
        izz="0.0069054" />
    </inertial>
    <visual>
      <origin
        xyz="0 0 0"
         rpy="1.57079632679 0 0" />
      <geometry>
    <!--  <mesh filename="package://robotican_armadillo/description/meshes/left_wheel_link.STL" /> -->
                 <cylinder  length="0.05" radius="0.095"/> 
      </geometry>
      <material
        name="">
        <color
          rgba="0.75294 0.75294 0.75294 1" />
      </material>
    </visual>
    <collision>
      <origin
        xyz="0 0 0"
        rpy="${M_PI/2} 0 0" />
      <geometry>
    <!--  <mesh filename="package://robotican_armadillo/description/meshes/left_wheel_link.STL" /> -->
                 <cylinder  length="0.05" radius="0.095"/> 
      </geometry>
    </collision>
  </link>
  <joint
    name="left_wheel_joint"
    type="continuous">
    <origin
      xyz="0 0.1642 0"
      rpy="0 0 0" />
    <parent
      link="base_link" />
    <child
      link="left_wheel_link" />
    <axis
      xyz="0 1 0" />
  </joint>
  <link
    name="right_wheel_link">
    <inertial>
      <origin
        xyz="-5.6549E-06 0.050799 0.030167"
        rpy="0 0 0" />
      <mass
        value="1.8524" />
      <inertia
        ixx="0.0069046"
        ixy="-3.8717E-08"
        ixz="-2.0707E-07"
        iyy="0.013153"
        iyz="1.0124E-07"
        izz="0.0069054" />
    </inertial>
    <visual>
      <origin
        xyz="0 0 0"
         rpy="${M_PI/2} 0 0" />
      <geometry>
    <!--  <mesh filename="package://robotican_armadillo/description/meshes/right_wheel_link.STL" /> -->
      <cylinder  length="0.05" radius="0.095"/>
      </geometry>
      <material
        name="">
        <color
          rgba="0.75294 0.75294 0.75294 1" />
      </material>
    </visual>
    <collision>
      <origin
        xyz="0 0 0"
        rpy="${M_PI/2} 0 0" />
      <geometry>
     <!--  <mesh filename="package://robotican_armadillo/description/meshes/right_wheel_link.STL" /> -->
      <cylinder  length="0.05" radius="0.095"/> 
      </geometry>
    </collision>
  </link>
  <joint
    name="right_wheel_joint"
    type="continuous">
    <origin
     xyz="0 -0.1642 0"
      rpy="0 0 0" />
    <parent
      link="base_link" />
    <child
      link="right_wheel_link" />
    <axis
      xyz="0 1 0" />
  </joint>
  <link
    name="laser_link">
    <inertial>
      <origin
        xyz="-5.6779E-05 6.3564E-05 -0.032003"
        rpy="0 0 0" />
      <mass
        value="0.13367" />
      <inertia
        ixx="7.0175E-05"
        ixy="-5.2416E-08"
        ixz="-1.6421E-07"
        iyy="7.0477E-05"
        iyz="-1.9232E-07"
        izz="4.6146E-05" />
    </inertial>
    <visual>
      <origin
        xyz="0 0 0"
        rpy="0 0 0" />
      <geometry>
        <mesh
          filename="package://robotican_armadillo/description/meshes/laser_link.STL" />
      </geometry>
      <material
        name="">
        <color
          rgba="0.29412 0.29412 0.29412 1" />
      </material>
    </visual>
    <collision>
      <origin
        xyz="0 0 0"
        rpy="0 0 0" />
      <geometry>
        <mesh
          filename="package://robotican_armadillo/description/meshes/laser_link.STL" />
      </geometry>
    </collision>
  </link>
  <joint
    name="laser_joint"
    type="fixed">
    <origin
      xyz="0.18961 0 0.1043"
      rpy="0 0 0" />
    <parent
      link="base_link" />
    <child
      link="laser_link" />
    <axis
      xyz="0 0 0" />
  </joint>
  
  
  
  
</robot>
