<?xml version="1.0"?>
<robot
  name="armadillo_torso_urdf" description="Armadillo robot torso">
    
  <link
    name="torso_link">
    <inertial>
      <origin
        xyz="0.0042842 2.8149E-05 0.03255"
        rpy="0 0 0" />
      <mass
        value="0.035511" />
      <inertia
        ixx="0.19579"
        ixy="2.4285E-05"
        ixz="-0.0045097"
        iyy="0.16807"
        iyz="-7.4938E-05"
        izz="0.072852" />
    </inertial>
    <visual>
      <origin
        xyz="0 0 0"
        rpy="0 0 0" />
      <geometry>
        <mesh
          filename="package://robotican_armadillo/description/meshes/torso_link.STL" />
      </geometry>
      <material
        name="">
        <color
          rgba="0.79216 0.81961 0.93333 1" />
      </material>
    </visual>
    <collision>
      <origin
        xyz="0 0 0"
        rpy="0 0 0" />
      <geometry>
        <mesh
          filename="package://robotican_armadillo/description/meshes/torso_link.STL" />
      </geometry>
    </collision>
  </link>
  <link
    name="rear_cam_link">
    <inertial>
      <origin
        xyz="-0.0060072 3.3793E-07 0.0005545"
        rpy="0 0 0" />
      <mass
        value="0.001942" />
      <inertia
        ixx="3.9185E-06"
        ixy="-2.0999E-11"
        ixz="-4.949E-08"
        iyy="2.1089E-06"
        iyz="-3.146E-10"
        izz="2.8316E-06" />
    </inertial>
    <visual>
      <origin
        xyz="0 0 0"
        rpy="0 0 0" />
      <geometry>
        <mesh
          filename="package://robotican_armadillo/description/meshes/rear_cam_link.STL" />
      </geometry>
      <material
        name="">
        <color
          rgba="0.29804 0.29804 0.29804 1" />
      </material>
    </visual>
    <collision>
      <origin
        xyz="0 0 0"
        rpy="0 0 0" />
      <geometry>
        <mesh
          filename="package://robotican_armadillo/description/meshes/rear_cam_link.STL" />
      </geometry>
    </collision>
  </link>
  <joint
    name="rear_cam_joint"
    type="fixed">
    <origin
      xyz="-0.09712 0 0.13354"
      rpy="0 0 3.1416" />
    <parent
      link="torso_link" />
    <child
      link="rear_cam_link" />
    <axis
      xyz="0 0 0" />
  </joint>
  <link
    name="arm_link">
    <inertial>
      <origin
        xyz="-0.0059684 -0.0015999 -0.0030639"
        rpy="0 0 0" />
      <mass
        value="0.0051572" />
      <inertia
        ixx="0.0028549"
        ixy="4.0212E-05"
        ixz="-9.0864E-06"
        iyy="0.0022217"
        iyz="-4.1689E-07"
        izz="0.0034029" />
    </inertial>
    <visual>
      <origin
        xyz="0 0 0"
        rpy="0 0 0" />
      <geometry>
        <mesh
          filename="package://robotican_armadillo/description/meshes/arm_link.STL" />
      </geometry>
      <material
        name="">
        <color
          rgba="0.79216 0.81961 0.93333 1" />
      </material>
    </visual>
    <collision>
      <origin
        xyz="0 0 0"
        rpy="0 0 0" />
      <geometry>
        <mesh
          filename="package://robotican_armadillo/description/meshes/arm_link.STL" />
      </geometry>
    </collision>
  </link>
  <joint
    name="arm_joint"
    type="fixed">
    <origin
      xyz="0.19338 0 -0.25204"
      rpy="0 0 0" />
    <parent
      link="torso_link" />
    <child
      link="arm_link" />
    <axis
      xyz="0 0 0" />
  </joint>
  <link
    name="head_link">
    <inertial>
      <origin
        xyz="-0.027036 -2.3647E-06 0.069774"
        rpy="0 0 0" />
      <mass
        value="0.059686" />
      <inertia
        ixx="0.00016122"
        ixy="-3.2007E-09"
        ixz="-2.9825E-05"
        iyy="0.0001219"
        iyz="1.8349E-09"
        izz="0.0001574" />
    </inertial>
    <visual>
      <origin
        xyz="0 0 0"
        rpy="0 0 0" />
      <geometry>
        <mesh
          filename="package://robotican_armadillo/description/meshes/head_link.STL" />
      </geometry>
      <material
        name="">
        <color
          rgba="0.25098 0.25098 0.25098 1" />
      </material>
    </visual>
    <collision>
      <origin
        xyz="0 0 0"
        rpy="0 0 0" />
      <geometry>
        <mesh
          filename="package://robotican_armadillo/description/meshes/head_link.STL" />
      </geometry>
    </collision>
  </link>
  <joint
    name="head_joint"
    type="fixed">
    <origin
      xyz="0.11288 0 0.26399"
      rpy="0 0 0" />
    <parent
      link="torso_link" />
    <child
      link="head_link" />
    <axis
      xyz="0 0 0" />
  </joint>
  <link
    name="head_pan_link">
    <inertial>
      <origin
        xyz="-0.0035721 -0.00092628 0.033004"
        rpy="0 0 0" />
      <mass
        value="0.03653" />
      <inertia
        ixx="3.6365E-05"
        ixy="-2.125E-07"
        ixz="-4.0004E-07"
        iyy="3.8545E-05"
        iyz="-4.6643E-07"
        izz="4.1521E-05" />
    </inertial>
    <visual>
      <origin
        xyz="0 0 0"
        rpy="0 0 0" />
      <geometry>
        <mesh
          filename="package://robotican_armadillo/description/meshes/head_pan_link.STL" />
      </geometry>
      <material
        name="">
        <color
          rgba="0.90588 0.44314 0.031373 1" />
      </material>
    </visual>
    <collision>
      <origin
        xyz="0 0 0"
        rpy="0 0 0" />
      <geometry>
        <mesh
          filename="package://robotican_armadillo/description/meshes/head_pan_link.STL" />
      </geometry>
    </collision>
  </link>
  <joint
    name="head_pan_joint"
    type="revolute">
    <origin
      xyz="-0.035 0 0.111"
      rpy="0 0 0" />
    <parent
      link="head_link" />
    <child
      link="head_pan_link" />
    <axis
      xyz="0 0 1" />
    <limit
      upper="${M_PI/3}"
	  lower="${-M_PI/3}"
      effort="3.1"
      velocity="7.016223585" /> 
  </joint>
  <link
    name="head_tilt_link">
    <inertial>
      <origin
        xyz="0.013688 0.00038551 0.064171"
        rpy="0 0 0" />
      <mass
        value="1.0232" />
      <inertia
        ixx="0.0056403"
        ixy="-2.0419E-05"
        ixz="1.476E-05"
        iyy="0.0012267"
        iyz="1.5926E-07"
        izz="0.0057848" />
    </inertial>
    <visual>
      <origin
        xyz="0 0 0"
        rpy="0 0 0" />
      <geometry>
        <mesh
          filename="package://robotican_armadillo/description/meshes/head_tilt_link.STL" />
      </geometry>
      <material
        name="">
        <color
          rgba="0.79216 0.81961 0.93333 1" />
      </material>
    </visual>
    <collision>
      <origin
        xyz="0 0 0"
        rpy="0 0 0" />
      <geometry>
        <mesh
          filename="package://robotican_armadillo/description/meshes/head_tilt_link.STL" />
      </geometry>
    </collision>
  </link>
  <joint
    name="head_tilt_joint"
    type="revolute">
    <origin
      xyz="0 0 0.051"
      rpy="0 0 0" />
    <parent
      link="head_pan_link" />
    <child
      link="head_tilt_link" />
    <axis
      xyz="0 1 0" />
    <limit
    upper="${M_PI/3}"
	  lower="${-M_PI/6}"
      effort="3.1"
      velocity="7.016223585" /> 
  </joint>
  <link
    name="kinect2_link">
    <inertial>

      <origin

        xyz="-0.034825 0.00047843 -0.0036931"

        rpy="0 0 0" />

      <mass

        value="0.82085" />

      <inertia

        ixx="0.0039702"

        ixy="-2.1546E-05"

        ixz="-2.6946E-05"

        iyy="0.00059235"

        iyz="-1.2194E-06"

        izz="0.0041195" />

    </inertial>
    <visual>
      <origin
        xyz="0 0 0"

        rpy="0 0 0" />
      <geometry>
        <mesh
          filename="package://robotican_armadillo/description/meshes/kinect2_link.STL" />
      </geometry>
      <material
        name="">
        <color
          rgba="0.15 0.15 0.15 1" />
      </material>
    </visual>
    <collision>
      <origin
        xyz="0 0 0"
        rpy="0 0 0" />
      <geometry>
        <mesh
          filename="package://robotican_armadillo/description/meshes/kinect2_link.STL" />
      </geometry>
    </collision>
  </link>
  <joint
    name="kinect2_joint"
    type="fixed">
    <origin
      xyz="0.0518 0 0.07225"
      rpy="0 0 0" />
    <parent
      link="head_tilt_link" />
    <child
      link="kinect2_link" />
    <axis
      xyz="0 0 0" />
  </joint>
  <joint name="kinect2_rgb_joint" type="fixed">
      <origin xyz="0 -0.0935 0" rpy="0 0 0"/>
      <parent link="kinect2_link"/>
      <child link="kinect2_rgb_frame" />
    </joint>
    
    <link name="kinect2_rgb_frame">
      <inertial>
	<mass value="0.001" />
	<origin xyz="0 0 0" />
	<inertia ixx="0.0001" ixy="0.0" ixz="0.0"
	  iyy="0.0001" iyz="0.0"
	  izz="0.0001" />
	</inertial>
      </link>   
      <joint name="kinect2_rgb_optical_joint" type="fixed">
	<origin xyz="0 0 0" rpy="${-M_PI/2} 0 ${-M_PI/2}" />
	<parent link="kinect2_rgb_frame" />
	<child link="kinect2_rgb_optical_frame" />
      </joint>
      
      <link name="kinect2_rgb_optical_frame">
	<inertial>
	  <mass value="0.001" />
	  <origin xyz="0 0 0" />
	  <inertia ixx="0.0001" ixy="0.0" ixz="0.0"
	    iyy="0.0001" iyz="0.0"
	    izz="0.0001" />
	  </inertial>
	</link>
	
	
	<joint name="kinect2_depth_joint" type="fixed">
	  <origin xyz="0 0 0" rpy="0 0 0" />
	  <parent link="kinect2_rgb_frame" />
	  <child link="kinect2_depth_frame" />
	</joint>
	
	<link name="kinect2_depth_frame">
	  <inertial>
	    <mass value="0.001" />
	    <origin xyz="0 0 0" />
	    <inertia ixx="0.0001" ixy="0.0" ixz="0.0"
	      iyy="0.0001" iyz="0.0"
	      izz="0.0001" />
	    </inertial>
	  </link>
	  
	  <joint name="kinect2_depth_optical_joint" type="fixed">
	    <origin xyz="0 0 0" rpy="${-M_PI/2} 0 ${-M_PI/2}" />
	    <parent link="kinect2_depth_frame" />
	    <child link="kinect2_depth_optical_frame" />
	  </joint>
	  <link name="kinect2_depth_optical_frame">
	    <inertial>
	      <mass value="0.001" />
	      <origin xyz="0 0 0" />
	      <inertia ixx="0.0001" ixy="0.0" ixz="0.0"
		iyy="0.0001" iyz="0.0"
		izz="0.0001" />
	      </inertial>
	    </link>  
</robot>
<!--       xyz="0.0518 -0.095 0.072265" -->
