<?xml version="1.0"?>

<robot xmlns:xacro="http://www.ros.org/wiki/xacro" name="armadillo2_robot" description="ARMadillo Robot">

 <xacro:property name="M_PI" value="3.1415926535897931" />


<link name="base_footprint"/>
  
 <joint name="base_footprint_joint" type="fixed">
    <parent link="base_footprint"/>
    <child link="base_link"/>
    <origin xyz="0.00 0.00 0.1" rpy="0.0 0.0 0.0"/>
  </joint> 

  <link
    name="base_link">
    <inertial>
      <origin
        xyz="-0.012353 0.000122 0.17716"
        rpy="0 0 0" />
      <mass
        value="50.6774" />
      <inertia
        ixx="50.61071"
        ixy="2.5604E-05"
        ixz="-0.080403"
        iyy="0.58359"
        iyz="-0.00032953"
        izz="0.35309" />
    </inertial>
    <visual>
      <origin
        xyz="0 0 0"
        rpy="0 0 0" />
      <geometry>
        <mesh
          filename="package://armadillo2_description/mesh/base_link.STL" />
      </geometry>
      <material
        name="">
        <color
          rgba="0.79216 0.81961 0.93333 1" />
      </material>
    </visual>
 <collision name='base_collision'>
       <origin
        xyz="0 0 0"
        rpy="0 0 0" />
      <geometry>
        <mesh
          filename="package://armadillo2_description/mesh/base_link.STL" />
      </geometry>
          </collision>

      <collision name='caster_collision'>
      <origin
        xyz="-0.3 0 -0.0385"
        rpy="0 0 0" />
            <geometry>
              <sphere radius="0.05"/>
            </geometry>
       <!--     <surface>
              <friction>
                <ode>
                  <mu>0</mu>
                  <mu2>0</mu2>
                  <slip1>1.0</slip1>
                  <slip2>1.0</slip2>
                </ode>
              </friction>
            </surface> -->
          </collision>
  </link>
  <link
    name="laser_link" />
  <joint
    name="laser_joint"
    type="fixed">
    <origin
      xyz="0.20337 0 0.143"
      rpy="0 0 0" />
    <parent
      link="base_link" />
    <child
      link="laser_link" />
    <axis
      xyz="0 0 0" />
  </joint>
  <link
    name="front_urf_link" />
  <joint
    name="front_urf_joint"
    type="fixed">
    <origin
      xyz="0.24229 0.00011161 0.068509"
      rpy="0 0 0" />
    <parent
      link="base_link" />
    <child
      link="front_urf_link" />
    <axis
      xyz="0 0 0" />
  </joint>

 <link
    name="left_wheel_link">
    <inertial>
      <origin
        xyz="9.16610941069373E-06 4.59070539915452E-09 8.0609835912647E-06"
        rpy="0 0 0" />
      <mass
        value="1.19468304707429" />
      <inertia
        ixx="0.00339394020641508"
        ixy="-1.7040091442662E-11"
        ixz="-3.19286008554441E-07"
        iyy="0.00640943262315833"
        iyz="-1.56330189682853E-11"
        izz="0.00339385794108548" />
    </inertial>
    <visual>
      <origin
        xyz="0 0 0"
        rpy="0 0 0" />
      <geometry>
        <mesh
          filename="package://armadillo2_description/mesh/left_wheel_link.STL" />
      </geometry>
      <material
        name="">
        <color
          rgba="0.792156862745098 0.819607843137255 0.933333333333333 1" />
      </material>
    </visual>
    <collision>
      <origin
        xyz="0 0 0"
        rpy="${M_PI/2} 0 0" />
      <geometry>
      <cylinder  length="0.04" radius="0.1"/> 
      </geometry>
    </collision>
  </link>


  <joint
    name="left_wheel_joint"
    type="continuous">
    <origin
      xyz="0.063115 0.16085 0.0115"
      rpy="0 0 0" />
    <parent
      link="base_link" />
    <child
      link="left_wheel_link" />
    <axis
      xyz="0 1 0" />
  </joint>

 <link
    name="right_wheel_link">
    <inertial>
      <origin
        xyz="9.16610941069373E-06 -4.99540929455033E-06 8.06098359126817E-06"
        rpy="0 0 0" />
      <mass
        value="1.19468304707429" />
      <inertia
        ixx="0.00339394020641508"
        ixy="-1.70400914487861E-11"
        ixz="-3.19286008554438E-07"
        iyy="0.00640943262315833"
        iyz="-1.5633018951093E-11"
        izz="0.00339385794108548" />
    </inertial>
    <visual>
      <origin
        xyz="0 0 0"
        rpy="0 0 0" />
      <geometry>
        <mesh
          filename="package://armadillo2_description/mesh/right_wheel_link.STL" />
      </geometry>
      <material
        name="">
        <color
          rgba="0.792156862745098 0.819607843137255 0.933333333333333 1" />
      </material>
    </visual>
   <collision>
      <origin
        xyz="0 0 0"
        rpy="${M_PI/2} 0 0" />
      <geometry>
      <cylinder  length="0.04" radius="0.1"/> 
      </geometry>
    </collision>
  </link>

  <joint
    name="right_wheel_joint"
    type="continuous">
    <origin
      xyz="0.063115 -0.16085 0.0115"
      rpy="0 0 0" />
    <parent
      link="base_link" />
    <child
      link="right_wheel_link" />
    <axis
      xyz="0 1 0" />
  </joint>

 <link
    name="caster_left_link">
    <inertial>
      <origin
        xyz="0.00421271931699432 -3.85330403696038E-08 0.0101595051394297"
        rpy="0 0 0" />
      <mass
        value="0.0496415739447828" />
      <inertia
        ixx="2.21176053576914E-05"
        ixy="-1.28190365189921E-11"
        ixz="5.51496344859667E-06"
        iyy="2.871220501461E-05"
        iyz="-3.35442196159029E-11"
        izz="1.10273416039652E-05" />
    </inertial>
    <visual>
      <origin
        xyz="0 0 0"
        rpy="0 0 0" />
      <geometry>
        <mesh
          filename="package://armadillo2_description/mesh/caster_left_link.STL" />
      </geometry>
      <material
        name="">
        <color
          rgba="0.792156862745098 0.819607843137255 0.933333333333333 1" />
      </material>
    </visual>
   
  </link>
  <joint
    name="caster_left_joint"
    type="fixed">
    <origin
      xyz="-0.221558374889189 0.168999999975415 -0.0596832588142329"
      rpy="0 0 0" />
    <parent
      link="base_link" />
    <child
      link="caster_left_link" />
    <axis
      xyz="0 0 0" />
  </joint>
  <link
    name="caster_right_link">
    <inertial>
      <origin
        xyz="0.00421271931699441 -3.85330403973594E-08 0.0101595051394299"
        rpy="0 0 0" />
      <mass
        value="0.049641573944783" />
      <inertia
        ixx="2.21176053576918E-05"
        ixy="-1.28190365160225E-11"
        ixz="5.5149634485968E-06"
        iyy="2.87122050146104E-05"
        iyz="-3.35442196090477E-11"
        izz="1.10273416039652E-05" />
    </inertial>
    <visual>
      <origin
        xyz="0 0 0"
        rpy="0 0 0" />
      <geometry>
        <mesh
          filename="package://armadillo2_description/mesh/caster_right_link.STL" />
      </geometry>
      <material
        name="">
        <color
          rgba="0.792156862745098 0.819607843137255 0.933333333333333 1" />
      </material>
    </visual>
   
  </link>
  <joint
    name="caster_right_joint"
    type="fixed">
    <origin
      xyz="-0.221558374889189 -0.168999999975416 -0.0596832588142329"
      rpy="0 0 0" />
    <parent
      link="base_link" />
    <child
      link="caster_right_link" />
    <axis
      xyz="0 0 0" />
  </joint>

  <link
    name="torso_link">
    <inertial>
      <origin
        xyz="-0.059733 -0.00037419 0.54938"
        rpy="0 0 0" />
      <mass
        value="4.9226" />
      <inertia
        ixx="0.27696"
        ixy="0.00010279"
        ixz="-0.051125"
        iyy="0.28305"
        iyz="-5.4525E-06"
        izz="0.10934" />
    </inertial>
    <visual>
      <origin
        xyz="0 0 0"
        rpy="0 0 0" />
      <geometry>
        <mesh
          filename="package://armadillo2_description/mesh/torso_link.STL" />
      </geometry>
      <material
        name="">
        <color
          rgba="0.79216 0.81961 0.93333 1" />
      </material>
    </visual>
    <collision>
      <origin
        xyz="0 0 0"
        rpy="0 0 0" />
      <geometry>
        <mesh
          filename="package://armadillo2_description/mesh/torso_link.STL" />
      </geometry>
    </collision>
  </link>
  <joint
    name="torso_joint"
      type="prismatic">
    <origin
      xyz="0 0 0"
      rpy="0 0 0" />
    <parent
      link="base_link" />
    <child
      link="torso_link" />
    <axis
      xyz="0 0 1" />
    <limit
      lower="0.02"
      upper="0.40"
      effort="500.0"
      velocity="0.1" />
  </joint>
  <link
    name="head_pan_link">
    <inertial>
      <origin
        xyz="0.0044497 -0.00020474 0.02363"
        rpy="0 0 0" />
      <mass
        value="0.038976" />
      <inertia
        ixx="2.9551E-05"
        ixy="-5.6247E-08"
        ixz="-4.9478E-06"
        iyy="3.8612E-05"
        iyz="1.0057E-09"
        izz="4.123E-05" />
    </inertial>
    <visual>
      <origin
        xyz="0 0 0"
        rpy="0 0 0" />
      <geometry>
        <mesh
          filename="package://armadillo2_description/mesh/head_pan_link.STL" />
      </geometry>
      <material
        name="">
        <color
          rgba="0.79216 0.81961 0.93333 1" />
      </material>
    </visual>
    <collision>
      <origin
        xyz="0 0 0"
        rpy="0 0 0" />
      <geometry>
        <mesh
          filename="package://armadillo2_description/mesh/head_pan_link.STL" />
      </geometry>
    </collision>
  </link>
  <joint
    name="head_pan_joint"
    type="revolute">
    <origin
      xyz="-0.055768 0 0.932"
      rpy="0 0 0" />
    <parent
      link="torso_link" />
    <child
      link="head_pan_link" />
    <axis
      xyz="0 0 1" />
    <limit
      upper="${3.1415926535897/3.0}"
      lower="${-3.1415926535897/3.0}"
      effort="3.1"
      velocity="7.016223585" /> 
  </joint>
  <link
    name="head_tilt_link">
    <inertial>
      <origin
        xyz="0.014321 0.00038338 0.064622"
        rpy="0 0 0" />
      <mass
        value="1.0412" />
      <inertia
        ixx="0.0059274"
        ixy="-2.0169E-05"
        ixz="2.5508E-05"
        iyy="0.0012759"
        iyz="1.129E-07"
        izz="0.0061424" />
    </inertial>
    <visual>
      <origin
        xyz="0 0 0"
        rpy="0 0 0" />
      <geometry>
        <mesh
          filename="package://armadillo2_description/mesh/head_tilt_link.STL" />
      </geometry>
      <material
        name="">
        <color
          rgba="0.79216 0.81961 0.93333 1" />
      </material>
    </visual>
    <collision>
      <origin
        xyz="0 0 0"
        rpy="0 0 0" />
      <geometry>
        <mesh
          filename="package://armadillo2_description/mesh/head_tilt_link.STL" />
      </geometry>
    </collision>
  </link>
  <joint
    name="head_tilt_joint"
    type="revolute">
    <origin
      xyz="0 0 0.041"
      rpy="0 0 0" />
    <parent
      link="head_pan_link" />
    <child
      link="head_tilt_link" />
    <axis
      xyz="0 1 0" />
    <limit
    upper="${M_PI/3}"
	  lower="${-M_PI/6}"
      effort="3.1"
      velocity="7.016223585" /> 
  </joint>
  <link
    name="kineckt_link" />
  <joint
    name="kineckt_joint"
    type="fixed">
    <origin
      xyz="0.053 0.0073569 0.070961"
      rpy="0 0 0" />
    <parent
      link="head_tilt_link" />
    <child
      link="kineckt_link" />
    <axis
      xyz="0 0 0" />
  </joint>
  <link
    name="rotation1_link">
    <inertial>
      <origin
        xyz="-3.5316E-10 0.0073117 0.032399"
        rpy="0 0 0" />
      <mass
        value="0.035317" />
      <inertia
        ixx="0.00055596"
        ixy="9.2522E-12"
        ixz="9.2226E-12"
        iyy="0.00016945"
        iyz="6.1918E-06"
        izz="0.00055286" />
    </inertial>
    <visual>
      <origin
        xyz="0 0 0"
        rpy="0 0 0" />
      <geometry>
        <mesh
          filename="package://armadillo2_description/mesh/rotation1_link.STL" />
      </geometry>
      <material
        name="">
        <color
          rgba="0.89804 0.91765 0.92941 1" />
      </material>
    </visual>
    <collision>
      <origin
        xyz="0 0 0"
        rpy="0 0 0" />
      <geometry>
        <mesh
          filename="package://armadillo2_description/mesh/rotation1_link.STL" />
      </geometry>
    </collision>
  </link>
  <joint
    name="rotation1_joint"
    type="revolute">
    <origin
      xyz="0.11617 0 0.3885"
      rpy="0 0 0" />
    <parent
      link="torso_link" />
    <child
      link="rotation1_link" />
    <axis
      xyz="0 0 1" />
       <limit
      effort="44.7"
      lower="-1.57"
      upper="1.57"
      velocity="2.0" /> <!--3.455751915-->
  </joint>
  <link
    name="shoulder1_link">
    <inertial>
      <origin
        xyz="0.01628 -0.03243 0.20044"
        rpy="0 0 0" />
      <mass
        value="0.052217" />
      <inertia
        ixx="0.0043595"
        ixy="-3.1405E-06"
        ixz="0.00053636"
        iyy="0.0041046"
        iyz="-5.2275E-05"
        izz="0.00081871" />
    </inertial>
    <visual>
      <origin
        xyz="0 0 0"
        rpy="0 0 0" />
      <geometry>
        <mesh
          filename="package://armadillo2_description/mesh/shoulder1_link.STL" />
      </geometry>
      <material
        name="">
        <color
          rgba="0.89804 0.91765 0.92941 1" />
      </material>
    </visual>
    <collision>
      <origin
        xyz="0 0 0"
        rpy="0 0 0" />
      <geometry>
        <mesh
          filename="package://armadillo2_description/mesh/shoulder1_link.STL" />
      </geometry>
    </collision>
  </link>
  <joint
    name="shoulder1_joint"
    type="revolute">
    <origin
      xyz="0 0.039 0.0335"
      rpy="0 0 0" />
    <parent
      link="rotation1_link" />
    <child
      link="shoulder1_link" />
    <axis
      xyz="0 1 0" />
    <limit
      effort="44.7"
      lower="-1.57"
      upper="1.95"
      velocity="2.0" /> <!--3.455751915-->
  </joint>
  <link
    name="shoulder2_link">
    <inertial>
      <origin
        xyz="0.068154 -0.020691 0.11032"
        rpy="0 0 0" />
      <mass
        value="0.047392" />
      <inertia
        ixx="0.00093237"
        ixy="-1.0052E-05"
        ixz="0.00048929"
        iyy="0.0012859"
        iyz="-1.3286E-05"
        izz="0.00091329" />
    </inertial>
    <visual>
      <origin
        xyz="0 0 0"
        rpy="0 0 0" />
      <geometry>
        <mesh
          filename="package://armadillo2_description/mesh/shoulder2_link.STL" />
      </geometry>
      <material
        name="">
        <color
          rgba="0.79216 0.81961 0.93333 1" />
      </material>
    </visual>
    <collision>
      <origin
        xyz="0 0 0"
        rpy="0 0 0" />
      <geometry>
        <mesh
          filename="package://armadillo2_description/mesh/shoulder2_link.STL" />
      </geometry>
    </collision>
  </link>
  <joint
    name="shoulder2_joint"
    type="revolute">
    <origin
      xyz="0.029998 -0.012 0.264"
      rpy="0 0 0" />
    <parent
      link="shoulder1_link" />
    <child
      link="shoulder2_link" />
    <axis
      xyz="0 1 0" />
    <limit
      effort="25.3"
      lower="-1.48"
      upper="2.3522"
      velocity="2.0" /> <!--3.455751915-->
  </joint>
  <link
    name="rotation2_link">
    <inertial>
      <origin
        xyz="5.0638E-06 -0.0012262 0.056857"
        rpy="0 0 0" />
      <mass
        value="0.01635" />
      <inertia
        ixx="0.00014092"
        ixy="1.0984E-09"
        ixz="1.6669E-08"
        iyy="8.0775E-05"
        iyz="-1.7606E-06"
        izz="0.00010647" />
    </inertial>
    <visual>
      <origin
        xyz="0 0 0"
        rpy="0 0 0" />
      <geometry>
        <mesh
          filename="package://armadillo2_description/mesh/rotation2_link.STL" />
      </geometry>
      <material
        name="">
        <color
          rgba="0.89804 0.91765 0.92941 1" />
      </material>
    </visual>
    <collision>
      <origin
        xyz="0 0 0"
        rpy="0 0 0" />
      <geometry>
        <mesh
          filename="package://armadillo2_description/mesh/rotation2_link.STL" />
      </geometry>
    </collision>
  </link>
  <joint
    name="rotation2_joint"
    type="revolute">
    <origin
      xyz="0.11667 -0.021 0.1591"
      rpy="1.3528E-11 0.7854 1.9131E-11" />
    <parent
      link="shoulder2_link" />
    <child
      link="rotation2_link" />
    <axis
      xyz="0 0 1" />
   <limit
      effort="25.3"
      lower="-1.57"
      upper="1.57"
      velocity="2.0" /> <!--3.455751915-->
  </joint>
  <link
    name="shoulder3_link">
    <inertial>
      <origin
        xyz="3.9875E-11 -0.044252 0.069689"
        rpy="0 0 0" />
      <mass
        value="0.015954" />
      <inertia
        ixx="0.00018198"
        ixy="2.1351E-13"
        ixz="-2.3815E-13"
        iyy="0.00015335"
        iyz="-5.6341E-06"
        izz="7.5641E-05" />
    </inertial>
    <visual>
      <origin
        xyz="0 0 0"
        rpy="0 0 0" />
      <geometry>
        <mesh
          filename="package://armadillo2_description/mesh/shoulder3_link.STL" />
      </geometry>
      <material
        name="">
        <color
          rgba="0.79216 0.81961 0.93333 1" />
      </material>
    </visual>
    <collision>
      <origin
        xyz="0 0 0"
        rpy="0 0 0" />
      <geometry>
        <mesh
          filename="package://armadillo2_description/mesh/shoulder3_link.STL" />
      </geometry>
    </collision>
  </link>
  <joint
    name="shoulder3_joint"
    type="revolute">
    <origin
      xyz="0 0.045 0.063"
      rpy="0 0 1.862E-16" />
    <parent
      link="rotation2_link" />
    <child
      link="shoulder3_link" />
    <axis
      xyz="0 1 0" />
    <limit
      effort="5.1"
      lower="-1.57"
      upper="1.57"
      velocity="2.0" /> <!--3.455751915-->
  </joint>
  <link
    name="wrist_link">
    <inertial>
      <origin
        xyz="-8.1889E-11 0.02077 -0.0027746"
        rpy="0 0 0" />
      <mass
        value="0.011365" />
      <inertia
        ixx="4.4099E-05"
        ixy="-1.2434E-13"
        ixz="-1.4422E-13"
        iyy="9.4421E-05"
        iyz="3.0209E-06"
        izz="0.00010114" />
    </inertial>
    <visual>
      <origin
        xyz="0 0 0"
        rpy="0 0 0" />
      <geometry>
        <mesh
          filename="package://armadillo2_description/mesh/wrist_link.STL" />
      </geometry>
      <material
        name="">
        <color
          rgba="0.86667 0.9098 1 1" />
      </material>
    </visual>
    <collision>
      <origin
        xyz="0 0 0"
        rpy="0 0 0" />
      <geometry>
        <mesh
          filename="package://armadillo2_description/mesh/wrist_link.STL" />
      </geometry>
    </collision>
  </link>
  <joint
    name="wrist_joint"
    type="revolute">
    <origin
      xyz="0 -0.045 0.123"
      rpy="1.5708 1.353E-11 1.5708" />
    <parent
      link="shoulder3_link" />
    <child
      link="wrist_link" />
    <axis
      xyz="0 1 0" />
 <limit
      effort="5.1"
      lower="-3.14"
      upper="3.14"
      velocity="2.0" /> <!--3.455751915-->
  </joint>

  <link name="gripper_link"/>

<joint name="gripper_joint" type="fixed">
    <origin xyz="0 0.06 0" rpy="${M_PI} 0 ${M_PI/2}"/>
    <parent link="wrist_link"/>
    <child link="gripper_link"/>
 </joint>


  <link
    name="left_finger_link">
    <inertial>
      <origin
        xyz="5.5511E-17 0.015598 0.034754"
        rpy="0 0 0" />
      <mass
        value="0.0017229" />
      <inertia
        ixx="1.4683E-05"
        ixy="-1.0482E-21"
        ixz="1.8423E-20"
        iyy="1.7304E-05"
        iyz="9.2811E-07"
        izz="4.5506E-06" />
    </inertial>
    <visual>
      <origin
        xyz="0 0 0"
        rpy="0 0 0" />
      <geometry>
        <mesh
          filename="package://armadillo2_description/mesh/left_finger_link.STL" />
      </geometry>
      <material
        name="">
        <color
          rgba="0.86667 0.9098 1 1" />
      </material>
    </visual>
    <collision>
      <origin
        xyz="0 0 0"
        rpy="0 0 0" />
      <geometry>
        <mesh
          filename="package://armadillo2_description/mesh/left_finger_link.STL" />
      </geometry>
    </collision>
  </link>
  <joint
    name="left_finger_joint"
    type="revolute">
    <origin
      xyz="0.025 0.03725 0"
      rpy="1.5708 -1.5708 ${M_PI}" />
    <parent
      link="wrist_link" />
    <child
      link="left_finger_link" />
    <axis
      xyz="1 0 0" />
    <limit
      effort="3.1"
      lower="-1.57"
      upper="1.57"
      velocity="2.0" /> <!--7.016223585-->
  </joint>
  <link
    name="right_finger_link">
    <inertial>
      <origin
        xyz="-1.1102E-16 -0.015598 0.034754"
        rpy="0 0 0" />
      <mass
        value="0.0017229" />
      <inertia
        ixx="1.4683E-05"
        ixy="2.0869E-20"
        ixz="-3.5787E-20"
        iyy="1.7304E-05"
        iyz="-9.2811E-07"
        izz="4.5506E-06" />
    </inertial>
    <visual>
      <origin
        xyz="0 0 0"
        rpy="0 0 0" />
      <geometry>
        <mesh
          filename="package://armadillo2_description/mesh/right_finger_link.STL" />
      </geometry>
      <material
        name="">
        <color
          rgba="0.86667 0.9098 1 1" />
      </material>
    </visual>
    <collision>
      <origin
        xyz="0 0 0"
        rpy="0 0 0" />
      <geometry>
        <mesh
          filename="package://armadillo2_description/mesh/right_finger_link.STL" />
      </geometry>
    </collision>
  </link>
  <joint
    name="right_finger_joint"
    type="revolute">
    <origin
      xyz="-0.025 0.03725 0"
      rpy="1.5708 -1.5708 ${M_PI}" />
    <parent
      link="wrist_link" />
    <child
      link="right_finger_link" />
    <axis
      xyz="1 0 0" />
  <limit
      effort="3.1"
      lower="-1.57"
      upper="1.57"
      velocity="2.0" /> <!--7.016223585-->
  </joint>
  <link
    name="softkinetic_link">
    <inertial>
      <origin
        xyz="-0.00023051 -1.5096E-05 -0.00085913"
        rpy="0 0 0" />
      <mass
        value="0.078763" />
      <inertia
        ixx="7.503E-05"
        ixy="-1.1534E-08"
        ixz="2.9297E-08"
        iyy="1.0654E-05"
        iyz="-1.0173E-09"
        izz="7.1732E-05" />
    </inertial>
    <visual>
      <origin
        xyz="0 0 0"
        rpy="0 0 0" />
      <geometry>
        <mesh
          filename="package://armadillo2_description/mesh/softkinetic_link.STL" />
      </geometry>
      <material
        name="">
        <color
          rgba="0.25098 0.25098 0.25098 1" />
      </material>
    </visual>
    <collision>
      <origin
        xyz="0 0 0"
        rpy="0 0 0" />
      <geometry>
        <mesh
          filename="package://armadillo2_description/mesh/softkinetic_link.STL" />
      </geometry>
    </collision>
  </link>
  <joint
    name="softkinetic_joint"
    type="fixed">
    <origin
      xyz="0 0.0143 -0.0598"
      rpy="-3.1416 6.1062E-16 1.5708" />
    <parent
      link="wrist_link" />
    <child
      link="softkinetic_link" />
    <axis
      xyz="0 0 0" />
  </joint>
  <link
    name="softkinetic_left_link" />
  <joint
    name="softkinetic_left_joint"
    type="fixed">
    <origin
      xyz="0.0083 0.0135 0"
      rpy="0 0 0" />
    <parent
      link="softkinetic_link" />
    <child
      link="softkinetic_left_link" />
    <axis
      xyz="0 0 0" />
  </joint>
  <link
    name="softkinetic_right_link" />
  <joint
    name="softkinetic_right_joint"
    type="fixed">
    <origin
      xyz="0.0083 -0.0135 0"
      rpy="-8.0779E-28 0 1.3535E-11" />
    <parent
      link="softkinetic_link" />
    <child
      link="softkinetic_right_link" />
    <axis
      xyz="0 0 0" />
  </joint>

</robot>
