<?xml version="1.0"?>

<robot
  name="robotican_manipulator_h" description="Manipulator H Arm" xmlns:xacro="http://www.ros.org/wiki/xacro">
  <xacro:property name="M_PI" value="3.1415926535897931" />

  <link
    name="base_arm_link">
    <inertial>
      <origin
        xyz="0.00022998 -5.8526E-11 -0.027818"
        rpy="0 0 0" />
      <mass
        value="0.32416" />
      <inertia
        ixx="0.00045599"
        ixy="1.2992E-13"
        ixz="-4.1813E-06"
        iyy="0.00045553"
        iyz="7.9519E-13"
        izz="0.00014363" />
    </inertial>
    <visual>
      <origin
        xyz="0 0 0"
        rpy="0 0 0" />
      <geometry>
        <mesh
          filename="package://robotican_manipulator_h/meshes/base_arm_link.STL" />
      </geometry>
      <material
        name="">
        <color
          rgba="0.89804 0.91765 0.92941 1" />
      </material>
    </visual>
    <collision>
      <origin
        xyz="0 0 0"
        rpy="0 0 0" />
      <geometry>
        <mesh
          filename="package://robotican_manipulator_h/meshes/base_arm_link.STL" />
      </geometry>
    </collision>
  </link>
  <link
    name="rotation1_link">
    <inertial>
      <origin
        xyz="-3.5191E-10 0.0073117 0.037899"
        rpy="0 0 0" />
      <mass
         value="0.35317" /> 
      <inertia
        ixx="0.00055596"
        ixy="9.2617E-12"
        ixz="9.2232E-12"
        iyy="0.00016945"
        iyz="6.1918E-06"
        izz="0.00055286" />
    </inertial>
    <visual>
      <origin
        xyz="0 0 0"
        rpy="0 0 0" />
      <geometry>
        <mesh
          filename="package://robotican_manipulator_h/meshes/rotation1_link.STL" />
      </geometry>
      <material
        name="">
        <color
          rgba="0.89804 0.91765 0.92941 1" />
      </material>
    </visual>
    <collision>
      <origin
        xyz="0 0 0"
        rpy="0 0 0" />
      <geometry>
        <mesh
          filename="package://robotican_manipulator_h/meshes/rotation1_link.STL" />
      </geometry>
    </collision>
  </link>
  <joint
    name="rotation1_joint"
    type="revolute">
    <origin
      xyz="0 0 0.03"
      rpy="0 0 0" />
    <parent
      link="base_arm_link" />
    <child
      link="rotation1_link" />
    <axis
      xyz="0 0 1" />
    <limit
      effort="44.7"
      lower="-1.57"
      upper="1.57"
      velocity="2.0" /> <!--3.455751915-->
  </joint>
  <link
    name="shoulder1_link">
    <inertial>
      <origin
        xyz="0.01628 0.00657 0.20044"
        rpy="0 0 0" />
      <mass
        value="0.52217" />
      <inertia
        ixx="0.0043595"
        ixy="-3.1405E-06"
        ixz="0.00053636"
        iyy="0.0041046"
        iyz="-5.2275E-05"
        izz="0.00081871" />
    </inertial>
    <visual>
      <origin
        xyz="0 0 0"
        rpy="0 0 0" />
      <geometry>
        <mesh
          filename="package://robotican_manipulator_h/meshes/shoulder1_link.STL" />
      </geometry>
      <material
        name="">
        <color
          rgba="0.75294 0.75294 0.75294 1" />
      </material>
    </visual>
    <collision>
      <origin
        xyz="0 0 0"
        rpy="0 0 0" />
      <geometry>
        <mesh
          filename="package://robotican_manipulator_h/meshes/shoulder1_link.STL" />
      </geometry>
    </collision>
  </link>
  <joint
    name="shoulder1_joint"
    type="revolute">
    <origin
      xyz="0 0 0.039"
      rpy="0 0 0" />
    <parent
      link="rotation1_link" />
    <child
      link="shoulder1_link" />
    <axis
      xyz="0 1 0" />
    <limit
      effort="44.7"
      lower="-1.57"
      upper="1.95"
      velocity="2.0" /> <!--3.455751915-->
  </joint>
  <link
    name="shoulder2_link">
<inertial>
      <origin
        xyz="0.068154 0.0063088 0.11032"
        rpy="0 0 0" />
      <mass
        value="0.47392" />
      <inertia
        ixx="0.00093237"
        ixy="-1.0052E-05"
        ixz="0.00048929"
        iyy="0.0012859"
        iyz="-1.3286E-05"
        izz="0.00091329" />
    </inertial>
    <visual>
      <origin
        xyz="0 0 0"
        rpy="0 0 0" />
      <geometry>
        <mesh
          filename="package://robotican_manipulator_h/meshes/shoulder2_link.STL" />
      </geometry>
      <material
        name="">
        <color
          rgba="0.75294 0.75294 0.75294 1" />
      </material>
    </visual>
    <collision>
      <origin
        xyz="0 0 0"
        rpy="0 0 0" />
      <geometry>
        <mesh
          filename="package://robotican_manipulator_h/meshes/shoulder2_link.STL" />
      </geometry>
    </collision>
  </link>
  <joint
    name="shoulder2_joint"
    type="revolute">
    <origin
      xyz="0.029998 0 0.264"
      rpy="0 0 0" />
    <parent
      link="shoulder1_link" />
    <child
      link="shoulder2_link" />
    <axis
      xyz="0 1 0" />
    <limit
      effort="25.3"
      lower="-1.48"
      upper="2.3522"
      velocity="2.0" /> <!--3.455751915-->
  </joint>
  <link
    name="rotation2_link">
 <inertial>
      <origin
        xyz="5.0638E-06 0.003816 0.026357"
        rpy="0 0 0" />
      <mass
        value="0.1635" />
      <inertia
        ixx="0.00014132"
        ixy="-3.0872E-09"
        ixz="1.6669E-08"
        iyy="8.0775E-05"
        iyz="3.4079E-06"
        izz="0.00010687" />
    </inertial>
    <visual>
      <origin
        xyz="0 0 0"
        rpy="0 0 0" />
      <geometry>
        <mesh
          filename="package://robotican_manipulator_h/meshes/rotation2_link.STL" />
      </geometry>
      <material
        name="">
        <color
          rgba="0.79216 0.81961 0.93333 1" />
      </material>
    </visual>
    <collision>
      <origin
        xyz="0 0 0"
        rpy="0 0 0" />
      <geometry>
        <mesh
          filename="package://robotican_manipulator_h/meshes/rotation2_link.STL" />
      </geometry>
    </collision>
  </link>
  <joint
    name="rotation2_joint"
    type="revolute">
    <origin
      xyz="0.13824 0.006 0.18067"
      rpy="-7.2737E-16 0.7854 -5.1433E-16" />
    <parent
      link="shoulder2_link" />
    <child
      link="rotation2_link" />
    <axis
      xyz="0 0 1" />
    <limit
      effort="25.3"
      lower="-1.57"
      upper="1.57"
      velocity="2.0" /> <!--3.455751915-->
  </joint>
  <link
    name="shoulder3_link">
 <inertial>
      <origin
        xyz="3.9874E-11 0.012748 0.069689"
        rpy="0 0 0" />
      <mass
        value="0.15954" />
      <inertia
        ixx="0.00018198"
        ixy="2.1351E-13"
        ixz="-2.3815E-13"
        iyy="0.00015335"
        iyz="-5.6341E-06"
        izz="7.5641E-05" />
    </inertial>
    <visual>
      <origin
        xyz="0 0 0"
        rpy="0 0 0" />
      <geometry>
        <mesh
          filename="package://robotican_manipulator_h/meshes/shoulder3_link.STL" />
      </geometry>
      <material
        name="">
        <color
          rgba="0.75294 0.75294 0.75294 1" />
      </material>
    </visual>
    <collision>
      <origin
        xyz="0 0 0"
        rpy="0 0 0" />
      <geometry>
        <mesh
          filename="package://robotican_manipulator_h/meshes/shoulder3_link.STL" />
      </geometry>
    </collision>
  </link>
  <joint
    name="shoulder3_joint"
    type="revolute">
    <origin
      xyz="0 -0.006 0.0325"
      rpy="1.3906E-15 0 1.3906E-15" />
    <parent
      link="rotation2_link" />
    <child
      link="shoulder3_link" />
    <axis
      xyz="0 1 0" />
    <limit
      effort="5.1"
      lower="-1.57"
      upper="1.57"
      velocity="2.0" /> <!--3.455751915-->
  </joint>
  <link
    name="wrist_link">
    <inertial>
      <origin
        xyz="-0.00053981 -8.915E-11 0.035177"
        rpy="0 0 0" />
      <mass
        value="0.098822" />
      <inertia
        ixx="6.6953E-05"
        ixy="5.9175E-12"
        ixz="1.6384E-06"
        iyy="3.364E-05"
        iyz="-2.8933E-12"
        izz="6.0712E-05" />
    </inertial>
    <visual>
      <origin
        xyz="0 0 0"
        rpy="0 0 0" />
      <geometry>
        <mesh
          filename="package://robotican_manipulator_h/meshes/wrist_link.STL" />
      </geometry>
      <material
        name="">
        <color
          rgba="0.79216 0.81961 0.93333 1" />
      </material>
    </visual>
    <collision>
      <origin
        xyz="0 0 0"
        rpy="0 0 0" />
      <geometry>
        <mesh
          filename="package://robotican_manipulator_h/meshes/wrist_link.STL" />
      </geometry>
    </collision>
  </link>
  <joint
    name="wrist_joint"
    type="revolute">
    <origin
      xyz="0 0.012 0.117"
      rpy="-8.0064E-16 0 -8.0064E-16" />
    <parent
      link="shoulder3_link" />
    <child
      link="wrist_link" />
    <axis
      xyz="0 0 1" />
    <limit
      effort="5.1"
      lower="-3.14"
      upper="3.14"
      velocity="2.0" /> <!--3.455751915-->
  </joint>
  
   <link name="gripper_link"/>

<joint name="gripper_joint" type="fixed">
    <origin xyz="0 0 0.06" rpy="0 ${-M_PI/2} 0"/>
    <parent link="wrist_link"/>
    <child link="gripper_link"/>
 </joint>
 
  <link
    name="left_finger_link">
    <inertial>
      <origin
        xyz="-5.5511E-17 0.015773 0.034449"
        rpy="0 0 0" />
      <mass
        value="0.017607" />
      <inertia
        ixx="1.4795E-05"
        ixy="-1.1493E-20"
        ixz="2.9858E-20"
        iyy="1.8029E-05"
        iyz="8.8323E-07"
        izz="5.2141E-06" />
    </inertial>
    <visual>
      <origin
        xyz="0 0 0"
        rpy="0 0 0" />
      <geometry>
        <mesh
          filename="package://robotican_manipulator_h/meshes/left_finger_link.STL" />
      </geometry>
      <material
        name="">
        <color
          rgba="0.86667 0.9098 1 1" />
      </material>
    </visual>
    <collision>
      <origin
        xyz="0 0 0"
        rpy="0 0 0" />
      <geometry>
        <mesh
          filename="package://robotican_manipulator_h/meshes/left_finger_link.STL" />
      </geometry>
    </collision>
  </link>
  <joint
    name="left_finger_joint"
    type="revolute">
    <origin
      xyz="0 0.021 0.04825"
      rpy="0.02578985 -1.1657E-15 8.0345E-16" />
    <parent
      link="wrist_link" />
    <child
      link="left_finger_link" />
    <axis
      xyz="1 0 0" />
    <limit
      effort="3.1"
      lower="-1.57"
      upper="1.57"
      velocity="2.0" /> <!--7.016223585-->
      <dynamics friction ="1000" damping="100"/>
  </joint>
  <link
    name="right_finger_link">
    <inertial>
      <origin
        xyz="2.2204E-16 -0.015773 0.034449"
        rpy="0 0 0" />
      <mass
        value="0.017607" />
      <inertia
        ixx="1.4795E-05"
        ixy="-4.8655E-21"
        ixz="6.7763E-21"
        iyy="1.8029E-05"
        iyz="-8.8323E-07"
        izz="5.2141E-06" />
    </inertial>
    <visual>
      <origin
        xyz="0 0 0"
        rpy="0 0 0" />
      <geometry>
        <mesh
          filename="package://robotican_manipulator_h/meshes/right_finger_link.STL" />
      </geometry>
      <material
        name="">
        <color
          rgba="0.86667 0.9098 1 1" />
      </material>
    </visual>
    <collision>
      <origin
        xyz="0 0 0"
        rpy="0 0 0" />
      <geometry>
        <mesh
          filename="package://robotican_manipulator_h/meshes/right_finger_link.STL" />
      </geometry>
    </collision>
  </link>
  <joint
    name="right_finger_joint"
    type="revolute">
    <origin
      xyz="0 -0.021 0.04825"
      rpy="-0.02578985 -3.3307E-16 1.0088E-15" />
    <parent
      link="wrist_link" />
    <child
      link="right_finger_link" />
    <axis
      xyz="1 0 0" />
    <limit
      effort="3.1"
      lower="-1.57"
      upper="1.57"
      velocity="2.0" /> <!--7.016223585-->
      <dynamics friction ="1000" damping="100"/>
  </joint>
  		
  <sensor_senz3d parent="wrist_link" name="softkinetic_camera" v_offset_x="0.045" v_offset_y="0.0" v_offset_z="0.0">
    <origin xyz="-0.05905 0 0.0753" rpy="0.0 -${M_PI/2} 0.0"/>
  </sensor_senz3d>
</robot>
